<?xml version='1.0' encoding='UTF-8'?>
<sdf version="1.7">
  <world name="Morphing_world">
      <physics type="ode">
      <max_step_size>0.001</max_step_size>
      <real_time_factor>1</real_time_factor>
      <real_time_update_rate>1000</real_time_update_rate>
      <ode>
        <solver>
          <type>quick</type>
          <iters>1500</iters>
          <sor>1.4</sor>
        </solver>
        <constraints>
          <cfm>0</cfm>
          <erp>1</erp>
          <contact_max_correcting_vel>0</contact_max_correcting_vel>
          <contact_surface_layer>0</contact_surface_layer>
        </constraints>
      </ode>
    </physics>

    <light type="directional" name="sun">
      <cast_shadows>true</cast_shadows>
      <pose>0 0 10 0 0 0</pose>
      <diffuse>0.8 0.8 0.8 1</diffuse>
      <specular>0.2 0.2 0.2 1</specular>
      <attenuation>
        <range>1000</range>
        <constant>0.9</constant>
        <linear>0.01</linear>
        <quadratic>0.001</quadratic>
      </attenuation>
      <direction>-0.5 0.1 -0.9</direction>
    </light>

    <model name="ground_plane">
      <static>true</static>
      <link name="link">
        <collision name="collision">
          <geometry>
            <plane>
              <normal>0 0 1</normal>
            </plane>
          </geometry>
          <surface>
            <friction>
              <ode>
                <mu>0.8</mu>
                <mu2>0.8</mu2>
              </ode>
            </friction>
          </surface>
        </collision>
        <visual name="visual">
          <geometry>
            <plane>
              <normal>0 0 1</normal>
              <size>100 100</size>
            </plane>
          </geometry>
          <material>
            <ambient>0.7 0.7 0.7 1</ambient>
            <diffuse>0.7 0.7 0.7 1</diffuse>
            <specular>0.7 0.7 0.7 1</specular>
          </material>
        </visual>
      </link>
    </model>

    <model name="Morphing_drone" canonical_link="body_link">
      <self_collide>true</self_collide>
      <pose>0 0 0.18 0 0 0</pose>
      <link name="body_link">
        <pose>0 0 0.033 0 0 0</pose>
        <collision name="body_collision">
          <pose>0 0 0.033 1.570796327 0 3.1415926535</pose>
          <geometry>
            <mesh>
              <uri>stl/body_link.stl</uri>
              <scale>0.001 0.001 0.001</scale>
            </mesh>
          </geometry>
          <surface>
            <contact/>
          </surface>
        </collision>
        <inertial>
          <pose>0.001705 0.000036 0.042196 0 0 0</pose>
          <mass>0.733</mass>
          <inertia>
            <ixx>0.001313892</ixx>
            <ixy>0</ixy>
            <ixz>-0.000018352 </ixz>
            <iyy>0.001655877</iyy>
            <iyz>0</iyz>
            <izz>0.002162122</izz>
          </inertia>
        </inertial>
        <visual name="body_visual">
          <pose>0 0 0.033 1.570796327 0 3.1415926535</pose>
          <geometry>
            <mesh>
              <uri>stl/body_link.stl</uri>
              <scale>0.001 0.001 0.001</scale>
            </mesh>
          </geometry>
        </visual>
      </link>
        <!-- COM에 추가할 가벼운 링크 -->
      <link name="com_force_link">
        <!-- 모델 전체 COM 위치 (body_link 기준 좌표계) -->
        <pose>0.002048 0.0000205 0.09248 0 0 0</pose>
        <inertial>
          <!-- 매우 작은 질량 -->
          <mass>1e-6</mass>
          <!-- 링크 고유 CoM은 링크 원점에 -->
          <pose>0 0 0 0 0 0</pose>
          <!-- 관성 모멘트도 작게 -->
          <inertia>
            <ixx>1e-9</ixx>
            <iyy>1e-9</iyy>
            <izz>1e-9</izz>
            <ixy>0</ixy>
            <ixz>0</ixz>
            <iyz>0</iyz>
          </inertia>
        </inertial>
      </link>
      <link name="Ycom_force_link">
        <!-- 모델 전체 COM 위치 (body_link 기준 좌표계) -->
        <pose>0.012548 0.0105205 0.09248 0 0 0</pose>
        <inertial>
          <!-- 매우 작은 질량 -->
          <mass>1e-6</mass>
          <!-- 링크 고유 CoM은 링크 원점에 -->
          <pose>0 0 0 0 0 0</pose>
          <!-- 관성 모멘트도 작게 -->
          <inertia>
            <ixx>1e-9</ixx>
            <iyy>1e-9</iyy>
            <izz>1e-9</izz>
            <ixy>0</ixy>
            <ixz>0</ixz>
            <iyz>0</iyz>
          </inertia>
        </inertial>
      </link>
      <link name="flare1_link">
        <pose relative_to="flare1_link_joint">0 0 0 0 0 0</pose>
        <collision name="flare1_collision">
          <pose relative_to="flare1_link_joint">0 0 0 1.570796327 0 1.570796327</pose>
          <geometry>
            <mesh>
              <uri>stl/flare_link.stl</uri>
              <scale>0.001 0.001 0.001</scale>
            </mesh>
          </geometry>
          <surface>
            <contact/>
          </surface>
        </collision>
        <inertial>
          <pose>0.106 0 0 0 0 0</pose>
          <mass>0.056</mass>
          <inertia>
            <ixx>0.000008703</ixx>
            <ixy>-0.000000006</ixy>
            <ixz>-0.000003319</ixz>
            <iyy>0.000187916</iyy>
            <iyz>0</iyz>
            <izz>0.000183866</izz>
          </inertia>
        </inertial>
        <visual name="flare1_visual">
          <pose relative_to="flare1_link_joint">0 0 0 1.570796327 0 1.570796327</pose>
          <geometry>
            <mesh>
              <uri>stl/flare_link.stl</uri>
              <scale>0.001 0.001 0.001</scale>
            </mesh>
          </geometry>
        </visual>
      </link>
      <link name="flare2_link">
        <pose relative_to="flare2_link_joint">0 0 0 0 0 0</pose>
        <collision name="flare2_collision">
          <pose relative_to="flare2_link_joint">0 0 0 1.570796327 0 1.570796327</pose>
          <geometry>
            <mesh>
              <uri>stl/flare_link.stl</uri>
              <scale>0.001 0.001 0.001</scale>
            </mesh>
          </geometry>
          <surface>
            <contact/>
          </surface>
        </collision>
        <inertial>
          <pose>0.106 0 0 0 0 0</pose>
          <mass>0.056</mass>
          <inertia>
            <ixx>0.000008703</ixx>
            <ixy>-0.000000006</ixy>
            <ixz>-0.000003319</ixz>
            <iyy>0.000187916</iyy>
            <iyz>0</iyz>
            <izz>0.000183866</izz>
          </inertia>
        </inertial>
        <visual name="flare2_visual">
          <pose relative_to="flare2_link_joint">0 0 0 1.570796327 0 1.570796327</pose>
          <geometry>
            <mesh>
              <uri>stl/flare_link.stl</uri>
              <scale>0.001 0.001 0.001</scale>
            </mesh>
          </geometry>
        </visual>
      </link>
      <link name="flare3_link">
        <pose relative_to="flare3_link_joint">0 0 0 0 0 0</pose>
        <collision name="flare3_collision">
          <pose relative_to="flare3_link_joint">0 0 0 1.570796327 0 1.570796327</pose>
          <geometry>
            <mesh>
              <uri>stl/flare_link.stl</uri>
              <scale>0.001 0.001 0.001</scale>
            </mesh>
          </geometry>
          <surface>
            <contact/>
          </surface>
        </collision>
        <inertial>
          <pose>0.106 0 0 0 0 0</pose>
          <mass>0.056</mass>
          <inertia>
            <ixx>0.000008703</ixx>
            <ixy>-0.000000006</ixy>
            <ixz>-0.000003319</ixz>
            <iyy>0.000187916</iyy>
            <iyz>0</iyz>
            <izz>0.000183866</izz>
          </inertia>
        </inertial>
        <visual name="flare3_visual">
          <pose relative_to="flare3_link_joint">0 0 0 1.570796327 0 1.570796327</pose>
          <geometry>
            <mesh>
              <uri>stl/flare_link.stl</uri>
              <scale>0.001 0.001 0.001</scale>
            </mesh>
          </geometry>
        </visual>
      </link>
      <link name="flare4_link">
        <pose relative_to="flare4_link_joint">0 0 0 0 0 0</pose>
        <collision name="flare4_collision">
          <pose relative_to="flare4_link_joint">0 0 0 1.570796327 0 1.570796327</pose>
          <geometry>
            <mesh>
              <uri>stl/flare_link.stl</uri>
              <scale>0.001 0.001 0.001</scale>
            </mesh>
          </geometry>
          <surface>
            <contact/>
          </surface>
        </collision>
        <inertial>
          <pose>0.106 0 0 0 0 0</pose>
          <mass>0.056</mass>
          <inertia>
            <ixx>0.000008703</ixx>
            <ixy>-0.000000006</ixy>
            <ixz>-0.000003319</ixz>
            <iyy>0.000187916</iyy>
            <iyz>0</iyz>
            <izz>0.000183866</izz>
          </inertia>
        </inertial>
        <visual name="flare4_visual">
          <pose relative_to="flare4_link_joint">0 0 0 1.570796327 0 1.570796327</pose>
          <geometry>
            <mesh>
              <uri>stl/flare_link.stl</uri>
              <scale>0.001 0.001 0.001</scale>
            </mesh>
          </geometry>
        </visual>
      </link>
      <link name="tilt1_link">
        <pose relative_to="tilt1_joint">0 0 0 0 0 0</pose>
        <collision name="tilt_1_collision">
          <pose relative_to="tilt1_joint">0 0 0 -1.570796327 0 0</pose>
          <geometry>
            <mesh>
              <uri> stl/tilt_link.stl</uri>
              <scale>0.001 0.001 0.001</scale>
            </mesh>
          </geometry>
          <surface>
            <contact/>
          </surface>
        </collision>
        <inertial>
          <pose>0 0 0.028 0 0 0 0</pose>
          <mass>0.065</mass>
          <inertia>
            <ixx>0.000009324</ixx>
            <ixy>0</ixy>
            <ixz>0</ixz>
            <iyy>0.000009685</iyy>
            <iyz>0</iyz>
            <izz>0.000007036</izz>
          </inertia>
        </inertial>
        <visual name="tilt_1">
          <pose relative_to="tilt1_joint">0 0 0 -1.570796327 0 0</pose>
          <geometry>
            <mesh>
              <uri> stl/tilt_link.stl</uri>
              <scale>0.001 0.001 0.001</scale>
            </mesh>
          </geometry>
        </visual>
      </link>
      <link name="tilt2_link">
        <pose relative_to="tilt2_joint">0 0 0 0 0 0</pose>
        <collision name="tilt_2_collision">
          <pose relative_to="tilt2_joint">0 0 0 -1.570796327 0 0</pose>
          <geometry>
            <mesh>
              <uri> stl/tilt_link.stl</uri>
              <scale>0.001 0.001 0.001</scale>
            </mesh>
          </geometry>
          <surface>
            <contact/>
          </surface>
        </collision>
        <inertial>
          <pose>0 0 0.028 0 0 0 0</pose>
          <mass>0.065</mass>
          <inertia>
            <ixx>0.000009324</ixx>
            <ixy>0</ixy>
            <ixz>0</ixz>
            <iyy>0.000009685</iyy>
            <iyz>0</iyz>
            <izz>0.000007036</izz>
          </inertia>
        </inertial>
        <visual name="tilt_2">
          <pose relative_to="tilt2_joint">0 0 0 -1.570796327 0 0</pose>
          <geometry>
            <mesh>
              <uri> stl/tilt_link.stl</uri>
              <scale>0.001 0.001 0.001</scale>
            </mesh>
          </geometry>
        </visual>
      </link>
      <link name="tilt3_link">
        <pose relative_to="tilt3_joint">0 0 0 0 0 0</pose>
        <collision name="tilt_3_collision">
          <pose relative_to="tilt3_joint">0 0 0 -1.570796327 0 0</pose>
          <geometry>
            <mesh>
              <uri> stl/tilt_link.stl</uri>
              <scale>0.001 0.001 0.001</scale>
            </mesh>
          </geometry>
          <surface>
            <contact/>
          </surface>
        </collision>
        <inertial>
          <pose>0 0 0.028 0 0 0 0</pose>
          <mass>0.065</mass>
          <inertia>
            <ixx>0.000009324</ixx>
            <ixy>0</ixy>
            <ixz>0</ixz>
            <iyy>0.000009685</iyy>
            <iyz>0</iyz>
            <izz>0.000007036</izz>
          </inertia>
        </inertial>
        <visual name="tilt_3">
          <pose relative_to="tilt3_joint">0 0 0 -1.570796327 0 0</pose>
          <geometry>
            <mesh>
              <uri> stl/tilt_link.stl</uri>
              <scale>0.001 0.001 0.001</scale>
            </mesh>
          </geometry>
        </visual>
      </link>
      <link name="tilt4_link">
        <pose relative_to="tilt4_joint">0 0 0 0 0 0</pose>
        <collision name="tilt_4_collision">
          <pose relative_to="tilt4_joint">0 0 0 -1.570796327 0 0</pose>
          <geometry>
            <mesh>
              <uri> stl/tilt_link.stl</uri>
              <scale>0.001 0.001 0.001</scale>
            </mesh>
          </geometry>
          <surface>
            <contact/>
          </surface>
        </collision>
        <inertial>
          <pose>0 0 0.028 0 0 0 0</pose>
          <mass>0.065</mass>
          <inertia>
            <ixx>0.000009324</ixx>
            <ixy>0</ixy>
            <ixz>0</ixz>
            <iyy>0.000009685</iyy>
            <iyz>0</iyz>
            <izz>0.000007036</izz>
          </inertia>
        </inertial>
        <visual name="tilt_4">
          <pose relative_to="tilt4_joint">0 0 0 -1.570796327 0 0</pose>
          <geometry>
            <mesh>
              <uri> stl/tilt_link.stl</uri>
              <scale>0.001 0.001 0.001</scale>
            </mesh>
          </geometry>
        </visual>
      </link>
      <link name="prop1_link">
        <pose relative_to="tilt1_joint">0 0 0.048 0 0 0</pose>
        <collision name="prop1_collision">
          <!-- <pose relative_to="tilt1_joint">0 0 0.048 0 0 0</pose> -->
          <geometry>
            <mesh>
              <uri> stl/prop_link.stl</uri>
              <scale>0.001 0.001 0.001</scale>
            </mesh>
          </geometry>
          <surface>
            <contact/>
          </surface>
        </collision>
        <inertial>
          <pose>0 0 0 0 0 0</pose>
          <mass>0.018</mass>
          <inertia>
            <ixx>0.0000282327</ixx>
            <ixy>0</ixy>
            <ixz>0</ixz>
            <iyy>0.0000282327</iyy>
            <iyz>0</iyz>
            <izz>0.0000560071</izz>
          </inertia>
        </inertial>
        <visual name="prop1_visual">
          <geometry>
            <mesh>
              <uri> stl/prop_link.stl</uri>
              <scale>0.001 0.001 0.001</scale>
            </mesh>
          </geometry>
        </visual>
      </link>
      <link name="prop2_link">
        <pose relative_to="tilt2_joint">0 0 0.048 0 0 0</pose>
        <collision name="prop2_collision">
          <geometry>
            <mesh>
              <uri> stl/prop_link.stl</uri>
              <scale>0.001 0.001 0.001</scale>
            </mesh>
          </geometry>
          <surface>
            <contact/>
          </surface>
        </collision>
        <inertial>
          <pose>0 0 0 0 0 0</pose>
          <mass>0.018</mass>
          <inertia>
            <ixx>0.0000282327</ixx>
            <ixy>0</ixy>
            <ixz>0</ixz>
            <iyy>0.0000282327</iyy>
            <iyz>0</iyz>
            <izz>0.0000560071</izz>
          </inertia>
        </inertial>
        <visual name="prop2_visual">
          <geometry>
            <mesh>
              <uri> stl/prop_link.stl</uri>
              <scale>0.001 0.001 0.001</scale>
            </mesh>
          </geometry>
        </visual>
      </link>
      <link name="prop3_link">
        <pose relative_to="tilt3_joint">0 0 0.048 0 0 0</pose>
        <collision name="prop3_collision">
          <geometry>
            <mesh>
              <uri> stl/prop_link.stl</uri>
              <scale>0.001 0.001 0.001</scale>
            </mesh>
          </geometry>
          <surface>
            <contact/>
          </surface>
        </collision>
        <inertial>
          <pose>0 0 0 0 0 0</pose>
          <mass>0.018</mass>
          <inertia>
            <ixx>0.0000282327</ixx>
            <ixy>0</ixy>
            <ixz>0</ixz>
            <iyy>0.0000282327</iyy>
            <iyz>0</iyz>
            <izz>0.0000560071</izz>
          </inertia>
        </inertial>
        <visual name="prop3_visual">
          <!-- <pose relative_to="tilt3_joint">0 0 0.048 0 0 0</pose> -->
          <geometry>
            <mesh>
              <uri> stl/prop_link.stl</uri>
              <scale>0.001 0.001 0.001</scale>
            </mesh>
          </geometry>
        </visual>
      </link>
      <link name="prop4_link">
        <pose relative_to="tilt4_joint">0 0 0.048 0 0 0</pose>
        <collision name="prop4_collision">
          <geometry>
            <mesh>
              <uri> stl/prop_link.stl</uri>
              <scale>0.001 0.001 0.001</scale>
            </mesh>
          </geometry>
          <surface>
            <contact/>
          </surface>
        </collision>
        <inertial>
          <pose>0 0 0 0 0 0</pose>
          <mass>0.018</mass>
          <inertia>
            <ixx>0.0000282327</ixx>
            <ixy>0</ixy>
            <ixz>0</ixz>
            <iyy>0.0000282327</iyy>
            <iyz>0</iyz>
            <izz>0.0000560071</izz>
          </inertia>
        </inertial>
        <visual name="prop4_visual">
          <geometry>
            <mesh>
              <uri> stl/prop_link.stl</uri>
              <scale>0.001 0.001 0.001</scale>
            </mesh>
          </geometry>
        </visual>
      </link>

      <link name="imu_link">
        <pose>0 0 0.001 0 0 0</pose>
        <visual name="visual">
          <geometry>
            <box>
              <size>0.001 0.001 0.001</size>
            </box>
          </geometry>
          <material>
            <ambient>1 0.5 0 1</ambient>
            <diffuse>1 0.5 0 1</diffuse>
            <specular>0.5 0.5 0.5 1</specular>
            <emissive>0 0 0 0</emissive>
          </material>
        </visual>
        <inertial>
          <mass>0.00001</mass>
          <pose>0 0 0 0 0 0</pose>
          <inertia>
            <ixx>0.00000001</ixx>
            <ixy>0.0</ixy>
            <ixz>0.0</ixz>
            <iyy>0.00000001</iyy>
            <iyz>0.0</iyz>
            <izz>0.00000001</izz>
          </inertia>
        </inertial>
        <sensor name="imu_sensor" type="imu">
          <pose>0 0 0 0 0 0</pose>
          <always_on>true</always_on>
          <update_rate>100</update_rate>
          <imu>
            <topic>imu</topic>
            <update_rate>100</update_rate>
            <orientation>
              <noise>
                <type>gaussian</type>
                <mean>0.0</mean>
                <stddev>0.01</stddev>
              </noise>
            </orientation>
            <angular_velocity>
              <noise>
                <type>gaussian</type>
                <mean>0.0</mean>
                <stddev>0.1</stddev>
              </noise>
            </angular_velocity>
            <linear_acceleration>
              <noise>
                <type>gaussian</type>
                <mean>0.0</mean>
                <stddev>0.1</stddev>
              </noise>
            </linear_acceleration>
          </imu>
          <plugin name="imu_plugin" filename="libgazebo_ros_imu_sensor.so">
            <ros>
              <namespace>/</namespace>
              <argument>~</argument>
            </ros>
            <bodyName>imu_link</bodyName>
            <topicName>imu</topicName>
            <updateRate>100.0</updateRate>
            <!-- <use_ned>true</use_ned> -->
            <gaussianNoise>0.0</gaussianNoise>
            <xyzOffset>0 0 0</xyzOffset>
            <rpyOffset>0 0 0</rpyOffset>
            <frameName>imu_link</frameName>
            <initial_orientation_as_reference>true</initial_orientation_as_reference>
          </plugin>
        </sensor>
      </link>
      <!-- <link name="gps_link">
        <pose>0 0 0.002 0 0 0</pose>
        <sensor name="gps_sensor" type="gps">
          <always_on>true</always_on>
          <update_rate>5</update_rate>
          <gps>
            <horizontal_noise>0.5</horizontal_noise>
            <vertical_noise>0.8</vertical_noise>
          </gps>
          <plugin name="gazebo_ros_gps_sensor" filename="libgazebo_ros_gps_sensor.so">
            <ros>
              <namespace>gps</namespace>
            </ros>
            <frameName>gps_link</frameName>
            <topicName>fix</topicName>
            <velocityTopicName>vel</velocityTopicName>
            <updateRate>5.0</updateRate>
          </plugin>
        </sensor>
      </link> -->
      <joint name="B2GPS" type="fixed">
        <parent>body_link</parent>
        <child>gps_link</child>
        <pose>0 0 0 0 0 0</pose>
      </joint>
      <joint name="B2IMU" type="fixed">
        <parent>body_link</parent>
        <child>imu_link</child>
        <pose>0 0 0 0 0 0</pose>
      </joint>
      <!--힘, 토크 작용점-->
      <joint name="com_force_joint" type="fixed">
        <parent>body_link</parent>
        <child>com_force_link</child>
        <!-- 이 조인트는 body_link 원점에 고정 -->
        <pose>0 0 0 0 0 0</pose>
      </joint>
      <joint name="Ycom_force_joint" type="fixed">
        <parent>body_link</parent>
        <child>Ycom_force_link</child>
        <!-- 이 조인트는 body_link 원점에 고정 -->
        <pose>0 0 0 0 0 0</pose>
      </joint>
      
      <joint name="flare1_link_joint" type="revolute">
        <parent>body_link</parent>
        <child>flare1_link</child>
        <pose relative_to="body_link">0.059776 0.057276 0.0555 0 0 0.7853981634</pose>
        <axis>
          <limit>
            <lower>-0.7853981634</lower>
            <upper>0.7853981634</upper>
            <effort>4.9</effort>
            <velocity>0.00000</velocity>
          </limit>
          <xyz>0.00000 0.00000 1.00000</xyz>
        </axis>
      </joint>
      <joint name="flare2_link_joint" type="revolute">
        <parent>body_link</parent>
        <child>flare2_link</child>
        <pose relative_to="body_link">0.059776 -0.057276 0.0555 0 0 -0.7853981634</pose>
        <axis>
          <limit>
            <lower>-0.7853981634</lower>
            <upper>0.7853981634</upper>
            <effort>4.9</effort>
            <velocity>0.00000</velocity>
          </limit>
          <xyz>0.00000 0.00000 1.00000</xyz>
        </axis>
      </joint>
      <joint name="flare3_link_joint" type="revolute">
        <parent>body_link</parent>
        <child>flare3_link</child>
        <pose relative_to="body_link">-0.054776 -0.057276 0.0555 0 0 -2.35619449</pose>
        <axis>
          <limit>
            <lower>-0.7853981634</lower>
            <upper>0.7853981634</upper>
            <effort>4.9</effort>
            <velocity>0.00000</velocity>
          </limit>
          <xyz>0.00000 0.00000 1.00000</xyz>
        </axis>
      </joint>
      <joint name="flare4_link_joint" type="revolute">
        <parent>body_link</parent>
        <child>flare4_link</child>
        <pose relative_to="body_link">-0.054776 0.057276 0.0555 0 0 2.35619449</pose>
        <axis>
          <limit>
            <lower>-0.7853981634</lower>
            <upper>0.7853981634</upper>
            <effort>4.9</effort>
            <velocity>0.00000</velocity>
          </limit>
          <xyz>0.00000 0.00000 1.00000</xyz>
        </axis>
      </joint>
      <joint name="tilt1_joint" type="revolute">
        <pose relative_to="flare1_link_joint">0.1595 0 0.0125 0 0 0</pose>
        <parent>flare1_link</parent>
        <child>tilt1_link</child>
        <axis>
          <limit>
            <lower>-1.570796327</lower>
            <upper>1.570796327</upper>
            <effort>0.98</effort>
            <velocity>0.00000</velocity>
           
          </limit>
          <xyz>1 0 0</xyz>
        </axis>
      </joint>
      <joint name="tilt2_joint" type="revolute">
        <pose relative_to="flare2_link_joint">0.1595 0 0.0125 0 0 0</pose>
        <parent>flare2_link</parent>
        <child>tilt2_link</child>
        <axis>
          <limit>
            <lower>-1.570796327</lower>
            <upper>1.570796327</upper>
            <effort>0.98</effort>
            <velocity>0.00000</velocity>
          </limit>
          <xyz>1 0 0</xyz>
        </axis>
      </joint>
      <joint name="tilt3_joint" type="revolute">
        <pose relative_to="flare3_link_joint">0.1595 0 0.0125 0 0 0</pose>
        <parent>flare3_link</parent>
        <child>tilt3_link</child>
        <axis>
          <limit>
            <lower>-1.570796327</lower>
            <upper>1.570796327</upper>
            <effort>0.98</effort>
            <velocity>0.00000</velocity>
          </limit>
          <xyz>1 0 0</xyz>
        </axis>
      </joint>
      <joint name="tilt4_joint" type="revolute">
        <pose relative_to="flare4_link_joint">0.1595 0 0.0125 0 0 0</pose>
        <parent>flare4_link</parent>
        <child>tilt4_link</child>
        <axis>
          <limit>
            <lower>-1.570796327</lower>
            <upper>1.570796327</upper>
            <effort>0.98</effort>
            <velocity>0.00000</velocity>
          </limit>
          <xyz>1 0 0</xyz>
        </axis>
      </joint>
      <joint name="prop1_joint" type="revolute">
        <pose relative_to="tilt1_joint">0 0 0.048 0 0 0</pose>
        <parent>tilt1_link</parent>
        <child>prop1_link</child>
        <axis>
          <xyz>0 0 1</xyz>
        </axis>
      </joint>
      <joint name="prop2_joint" type="revolute">
        <pose relative_to="tilt2_joint">0 0 0.048 0 0 0</pose>
        <parent>tilt2_link</parent>
        <child>prop2_link</child>
        <axis>
          <xyz>0 0 1</xyz>
        </axis>
      </joint>
      <joint name="prop3_joint" type="revolute">
        <pose relative_to="tilt3_joint">0 0 0.048 0 0 0</pose>
        <parent>tilt3_link</parent>
        <child>prop3_link</child>
        <axis>
          <xyz>0 0 1</xyz>
        </axis>
      </joint>
      <joint name="prop4_joint" type="revolute">
        <pose relative_to="tilt4_joint">0 0 0.048 0 0 0</pose>
        <parent>tilt4_link</parent>
        <child>prop4_link</child>
        <axis>
          <xyz>0 0 1</xyz>
        </axis>
      </joint>

      
      <!-- main 모터 -->
      <plugin name="motor1" filename="libgazebo_motor_model_ros.so">
        <robotNamespace>my_drone</robotNamespace>
        <jointName>prop1_joint</jointName>
      </plugin>
      <plugin name="motor2" filename="libgazebo_motor_model_ros.so">
        <robotNamespace>my_drone</robotNamespace>
        <jointName>prop2_joint</jointName>
      </plugin>
      <plugin name="motor3" filename="libgazebo_motor_model_ros.so">
        <robotNamespace>my_drone</robotNamespace>
        <jointName>prop3_joint</jointName>
      </plugin>
      <plugin name="motor4" filename="libgazebo_motor_model_ros.so">
        <robotNamespace>my_drone</robotNamespace>
        <jointName>prop4_joint</jointName>
      </plugin>

      <!-- flare 모터 -->
      <plugin name="motor_flare1" filename="libgazebo_motor_model_ros.so">
        <robotNamespace>my_drone</robotNamespace>
        <jointName>flare1_link_joint</jointName>
      </plugin>
      <plugin name="motor_flare2" filename="libgazebo_motor_model_ros.so">
        <robotNamespace>my_drone</robotNamespace>
        <jointName>flare2_link_joint</jointName>
      </plugin>
      <plugin name="motor_flare3" filename="libgazebo_motor_model_ros.so">
        <robotNamespace>my_drone</robotNamespace>
        <jointName>flare3_link_joint</jointName>
      </plugin>
      <plugin name="motor_flare4" filename="libgazebo_motor_model_ros.so">
        <robotNamespace>my_drone</robotNamespace>
        <jointName>flare4_link_joint</jointName>
      </plugin>

      <!-- tilt 모터 -->
      <plugin name="motor_tilt1" filename="libgazebo_motor_model_ros.so">
        <robotNamespace>my_drone</robotNamespace>
        <jointName>tilt1_joint</jointName>
      </plugin>
      <plugin name="motor_tilt2" filename="libgazebo_motor_model_ros.so">
        <robotNamespace>my_drone</robotNamespace>
        <jointName>tilt2_joint</jointName>
      </plugin>
      <plugin name="motor_tilt3" filename="libgazebo_motor_model_ros.so">
        <robotNamespace>my_drone</robotNamespace>
        <jointName>tilt3_joint</jointName>
      </plugin>
      <plugin name="motor_tilt4" filename="libgazebo_motor_model_ros.so">
        <robotNamespace>my_drone</robotNamespace>
        <jointName>tilt4_joint</jointName>
      </plugin>

      <plugin name="joint_state_publisher"
              filename="libgazebo_ros_joint_state_publisher.so">
        <robotNamespace>my_drone</robotNamespace>
        <!-- publish_rate 가 아니라 update_rate -->
        <update_rate>50</update_rate>

        <!-- jointName 이 아니라 joint_name -->
        <joint_name>prop1_joint</joint_name>
        <joint_name>prop2_joint</joint_name>
        <joint_name>prop3_joint</joint_name>
        <joint_name>prop4_joint</joint_name>

        <!-- flare -->
        <joint_name>flare1_link_joint</joint_name>
        <joint_name>flare2_link_joint</joint_name>
        <joint_name>flare3_link_joint</joint_name>
        <joint_name>flare4_link_joint</joint_name>

        <!-- tilt -->
        <joint_name>tilt1_joint</joint_name>
        <joint_name>tilt2_joint</joint_name>
        <joint_name>tilt3_joint</joint_name>
        <joint_name>tilt4_joint</joint_name>
      </plugin>

      <plugin name="pose_publisher" filename="libgazebo_ros_p3d.so">
        <ros>
          <namespace>/my_drone</namespace>
          <remapping>~/pose:=pose</remapping>
        </ros>
        <alwaysOn>true</alwaysOn>
        <updateRate>100.0</updateRate>
        <body_name>body_link</body_name>
        <gaussianNoise>0.0</gaussianNoise>
        <frameId>world</frameId>
      </plugin>

    </model>
  </world>
</sdf>